<?xml version="1.0"?>
<robot name="europa_explorer_v1" xmlns:xacro="http://www.ros.org/wiki/xacro">

  <!-- Chassis -->
  <link name="chassis">
    <visual>
      <origin xyz="0 0 0.3" rpy="0 0 0"/>
      <geometry>
        <box size="1.0 0.6 0.4"/>
      </geometry>
      <material name="white">
        <color rgba="1 1 1 1"/>
      </material>
    </visual>
    <collision>
      <origin xyz="0 0 0.3" rpy="0 0 0"/>
      <geometry>
        <box size="1.0 0.6 0.4"/>
      </geometry>
    </collision>
    <inertial>
      <origin xyz="0 0 0.3" rpy="0 0 0"/>
      <mass value="50"/>
      <inertia ixx="2.5" ixy="0" ixz="0" iyy="13.0" iyz="0" izz="13.0"/>
    </inertial>
  </link>

  <!-- Wheels -->
  <!-- front left -->
  <link name="front_left_wheel">
    <visual>
      <origin xyz="0.4 0.4 0" rpy="0 0 0"/>
      <geometry>
        <cylinder radius="0.2" length="0.2"/>
      </geometry>
      <material name="black">
        <color rgba="0 0 0 1"/>
      </material>
    </visual>
    <collision>
      <origin xyz="0.4 0.4 0" rpy="0 0 0"/>
      <geometry>
        <cylinder radius="0.2" length="0.2"/>
      </geometry>
    </collision>
    <inertial>
      <origin xyz="0.4 0.4 0"/>
      <mass value="5"/>
      <inertia ixx="0.02" ixy="0" ixz="0" iyy="0.02" iyz="0" izz="0.01"/>
    </inertial>
  </link>

  <joint name="front_left_wheel_joint" type="continuous">
    <parent link="chassis"/>
    <child link="front_left_wheel"/>
    <origin xyz="0.4 0.4 0" rpy="0 0 0"/>
    <axis xyz="0 1 0"/>
  </joint>

  <!-- front right -->
  <link name="front_right_wheel">
    <visual>
      <origin xyz="0.4 -0.4 0" rpy="0 0 0"/>
      <geometry><cylinder radius="0.2" length="0.2"/></geometry>
      <material name="black"><color rgba="0 0 0 1"/></material>
    </visual>
    <collision>
      <origin xyz="0.4 -0.4 0"/>
      <geometry><cylinder radius="0.2" length="0.2"/></geometry>
    </collision>
    <inertial>
      <origin xyz="0.4 -0.4 0"/>
      <mass value="5"/>
      <inertia ixx="0.02" ixy="0" ixz="0" iyy="0.02" iyz="0" izz="0.01"/>
    </inertial>
  </link>

  <joint name="front_right_wheel_joint" type="continuous">
    <parent link="chassis"/>
    <child link="front_right_wheel"/>
    <origin xyz="0.4 -0.4 0" rpy="0 0 0"/>
    <axis xyz="0 1 0"/>
  </joint>

  <!-- rear left -->
  <link name="back_left_wheel">
    <visual>
      <origin xyz="-0.4 0.4 0" rpy="0 0 0"/>
      <geometry><cylinder radius="0.2" length="0.2"/></geometry>
      <material name="black"><color rgba="0 0 0 1"/></material>
    </visual>
    <collision>
      <origin xyz="-0.4 0.4 0"/>
      <geometry><cylinder radius="0.2" length="0.2"/></geometry>
    </collision>
    <inertial>
      <origin xyz="-0.4 0.4 0"/>
      <mass value="5"/>
      <inertia ixx="0.02" ixy="0" ixz="0" iyy="0.02" iyz="0" izz="0.01"/>
    </inertial>
  </link>

  <joint name="back_left_wheel_joint" type="continuous">
    <parent link="chassis"/>
    <child link="back_left_wheel"/>
    <origin xyz="-0.4 0.4 0" rpy="0 0 0"/>
    <axis xyz="0 1 0"/>
  </joint>

  <!-- rear right -->
  <link name="back_right_wheel">
    <visual>
      <origin xyz="-0.4 -0.4 0" rpy="0 0 0"/>
      <geometry><cylinder radius="0.2" length="0.2"/></geometry>
      <material name="black"><color rgba="0 0 0 1"/></material>
    </visual>
    <collision>
      <origin xyz="-0.4 -0.4 0"/>
      <geometry><cylinder radius="0.2" length="0.2"/></geometry>
    </collision>
    <inertial>
      <origin xyz="-0.4 -0.4 0"/>
      <mass value="5"/>
      <inertia ixx="0.02" ixy="0" ixz="0" iyy="0.02" iyz="0" izz="0.01"/>
    </inertial>
  </link>

  <joint name="back_right_wheel_joint" type="continuous">
    <parent link="chassis"/>
    <child link="back_right_wheel"/>
    <origin xyz="-0.4 -0.4 0" rpy="0 0 0"/>
    <axis xyz="0 1 0"/>
  </joint>

</robot>

